<?xml version='1.0'?>
<sdf version='1.4'>
  <model name="lever_real">
  <static>false</static>
    <link name='base'>
      <pose>0 0 .25 0 0 0</pose>
      <inertial>
        <mass>2.25</mass>
      </inertial>
        <collision name='collision'>
          <geometry>
            <box>
              <size>.5 .5 .5</size>
            </box>
          </geometry>
        </collision>
        <visual name='visual'>
          <geometry>
            <box>
              <size>.5 .5 .5</size>
            </box>
          </geometry>
        </visual>
      </link>
      
      <joint type= "revolute" name="stuck">
        <pose>0 0 0 0 0 0</pose>
        <child>base</child>
        <parent>world</parent>
      </joint>
      
      <link name='arm'>
        <pose>0 0 1 0 0 0</pose>
        <inertial>
          <mass>.5</mass>
          <auto>true</auto>
        </inertial>
         <collision name='collision'>
           <geometry>
             <cylinder>
               <radius>.05</radius>
               <length>1</length>
             </cylinder>
           </geometry>
         </collision>
         <visual name='visual'>
           <geometry>
             <cylinder>
               <radius>.05</radius>
               <length>1</length>
             </cylinder>
           </geometry>
         </visual>
       </link>
       
       <joint type="revolute" name="fulcrum">
        <pose>0 0 -.5 0 0 0</pose>
        <child>arm</child>
        <parent>base</parent>
        <axis>
          <xyz>0 1 0</xyz>
          <dynamics>
            <friction>5</friction>
          </dynamics>
          <limit>
            <lower>-.785</lower>
            <upper>.785</upper>
          </limit>
        </axis>
      </joint>
  </model>
</sdf>
